Workbook

Sheet Read me
A1: The Compute Question, Part 2: the model
A2: By | B2: Mark A, Veritas Research. Companion spreadsheet to the article The Compute Question, Part 2 (October 2026).
A4: What the model does
B5: It asks when demand for AI tokens could outgrow the data center capacity built to serve it in North America, year by year from 2026 to 2036.
B6: It runs eight demand paths (S1 to S8) against three supply paths (Low, Base, High), which gives 24 pairings.
B7: For each pairing it finds the first year demand passes 85% of capacity (a squeeze, where rationing and price rises are assumed to start) and the first year it passes 100% (a shortage).
B8: Weights on each demand path and each supply path turn those 24 answers into odds.
B9: Supply in tokens per day = capacity in gigawatts x share used for inference x share serving language models x change in utilization x throughput per megawatt x tokens per watt index x memory gate factor.
B10: Demand starts from tokens served today and grows along each path, with growth fading over time.
A12: How to use it
B13: Change only the blue cells, and only on the Inputs sheet. Every other number is a formula, so one change ripples through every sheet.
B14: Start with the switches in Inputs section 1: the supply path used on the load rows, the demand unit, a training shift, the memory gate and the High path slippage haircut.
B15: The odds weights are in Inputs section 10. Demand weights should sum to 100 and supply weights to 100; the check rows show the totals.
B16: To test the two numbers nobody publishes, try 12 and 20 GW for capacity today and 0.6 and 1.0 for throughput (Inputs section 3).
A18: What each sheet does
A19: Read me | B19: This page.
A20: Inputs | B20: Every assumption, with its unit, source and evidence label. The only sheet you need to edit.
A21: North America | B21: Year by year supply for each supply path, demand for each demand path, load (demand as a share of supply), the memory gate, and helper rows that feed the Matrix.
A22: Matrix | B22: The first squeeze year and first shortage year for every demand and supply pairing.
A23: Odds | B23: The weighted share of pairings that reach a squeeze or a shortage by each horizon year, plus today's load.
A24: Worker check | B24: A side cross check: how much token demand North American workers alone could explain. It does not feed the model.
A26: Evidence labels used on the Inputs sheet
A27: Verified | B27: The author opened the company filing, release, regulator page or dataset.
A28: Reported | B28: A named outlet reported it, or a person said it on the record, but the underlying document was not seen.
A29: Secondhand | B29: Found only through summaries, call transcripts or aggregators.
A30: Estimate | B30: An analyst model, a research group's model, or the author's own arithmetic. A range, not a fact.
A31: Setting | B31: A switch or choice for the reader, not a claim about the world.
A33: Key caveats
B34: Two of the most important inputs are unpublished: how much AI capacity is running in North America today, and how many tokens a megawatt really serves. Both are the author's estimates. Depending on them, today's load could sit anywhere from about 36% to 100%; the central case is about 60%.
B35: The 85% squeeze line is an assumption, not a measurement. Market signals (rents, vacancy, supplier statements) behave as if the fleet were fuller than the central case says.
B36: The odds are low confidence. They are weights the author chose, applied to paths the author built. They describe how much of the scenario space ends in a squeeze; they are not a forecast.
B37: Efficiency after 2027 is the 2027 gain faded year by year, not researched separately for 2028 onward.
B38: Demand is stated in 2026 mix equivalents. The compute weighted unit discounts input and cached tokens with estimated weights.
B39: Columns are mid year. 2032 to 2036 are a rough extension.
A41: License | B41: Mark A, Veritas Research, CC BY 4.0. Not investment advice.

Sheet Inputs
A1: Inputs: every assumption in the model
A2: Every variable sits on this sheet. Change only the blue cells; the North America, Matrix, Odds and Worker check sheets recalculate from here. Demand and supply are in trillion tokens per day, stated in 2026 mix equivalents.
A3: Evidence labels, as in the article: Verified (the author checked the source document), Reported (a named outlet or an on the record statement), Secondhand (summaries, call transcripts or aggregators), Estimate (an analyst or research group model, or the author's own arithmetic). Setting means a switch or choice for the reader.
A5: Input | B5: Value | E5: Unit | F5: Source or note | G5: Evidence
A6: 1. Scenario switches (change these first)
A7: Supply path used on the load rows | B7: 2 | E7: 1 = Low, 2 = Base, 3 = High | F7: Sets which supply path the load rows on the North America sheet divide by. The Matrix and Odds sheets always use all three paths. | G7: Setting
A8: Demand unit | B8: 2 | E8: 1 = raw tokens, 2 = compute weighted | F8: Compute weighted (the default) discounts input and cached tokens by their compute cost. Raw tokens match what companies publish but overstate load, because cached rereads cost far less than new output. | G8: Setting
A9: Extra share of AI compute moved to training | B9: 0 | E9: percentage points (try 0, 10 or 20) | F9: 0 keeps today's split between training and inference. 10 or 20 moves that many points of compute from inference to training from 2027. | G9: Setting
A10: Memory gate on 2027 supply | B10: 1 | E10: 1 = on, 0 = off | F10: Memory chip output for 2027 is largely committed already: Micron said on its 30 September 2026 earnings call that more than 75% of 2027 output is committed and that new clean rooms arrive from late 2028 (Secondhand, call transcript). When on, no supply path may grow effective capacity in 2027 faster than the cap in section 7. At the default cap it binds only on the High path. | G10: Setting
A11: High path slippage haircut | B11: 1 | E11: 1 = on, 0 = off | F11: When on, the High path's 2027 additions are cut by the slippage share in section 7, because not every announced project lands on time. | G11: Setting
A12: Count idle time once | B12: 1 | E12: 1 = yes (default), 0 = no | F12: The throughput figure in section 3 is calibrated to what Google and OpenAI actually deliver, so it already includes idle time. With 1, the model applies only the change in utilization after 2026. With 0 it applies utilization a second time, which understates supply; 0 is kept only as a check. | G12: Setting
A14: 2. Demand today (mid 2026)
A15: Tokens served per day outside China, all labs | B15: 250 | E15: trillion tokens per day | F15: Range 190 to 300. Google 107 trillion a day (May 2026, Verified). OpenAI about 35 to 40 trillion in mid 2026 (its application programming interface (API) passed 21.6 trillion a day on 31 March 2026, Verified, plus growth and ChatGPT). Anthropic does not disclose (tracker estimate 32 trillion, range 14 to 69). Cross checks: an outside desk research estimate of 190 (150 to 275); tokensperday.com disclosed US floor of 160 (July 2026); Exponential View via Epoch AI, 432 global less about 140 for China, so about 290. | G15: Estimate
A16: Share of that demand served from North American data centers | B16: 0.75 | E16: share | F16: North America is 47% of OpenRouter spend, but most demand from other regions is also served from US data centers (Epoch AI: tracked sites are predominantly in the US). | G16: Estimate
A18: 3. Capacity today (mid 2026): the two numbers nobody publishes
A19: North American AI data center capacity in operation | B19: 15 | E19: gigawatts (GW) of information technology (IT) power for AI | F19: No primary source publishes this. Outside figures point to about 11 GW (end 2025) to 19 GW (end 2026); Bloomberg Intelligence about 9 GW live (March 2026, scope unclear). Epoch AI tracks 13.6 GW at 93 frontier sites (30 September 2026), mostly in the US. Treat it as a range and try 12 and 20. At 12 GW, today's load is about 75%. | G19: Estimate
A20: Fleet average throughput in real service, 2026 | B20: 0.8 | E20: million tokens per second per megawatt (MW) | F20: Tokens delivered per second per MW of language model inference capacity, idle time included. Google: about 107 trillion a day on roughly 1.2 GW of inference, about 1.0. OpenAI: roughly 50 trillion a day on roughly 1 GW, about 0.6. Central case is the midpoint, 0.8; try 0.6 and 1.0. Benchmark best cases are far higher: H200 2.26, B200 6.95, GB300 21 to 28.5 (SemiAnalysis InferenceX, September 2026, one open model). | G20: Estimate
A22: 4. How capacity turns into tokens
A23: Share of AI compute used for inference, 2026 | B23: 0.5 | E23: share | F23: McKinsey (February 2026): 47.5% in 2025, 60% in 2030, power basis. Epoch AI: OpenAI roughly half in 2025. Range 45% to 65%. | G23: Estimate
A24: Yearly rise in inference share | B24: 0.025 | E24: percentage points a year | F24: McKinsey path: 47.5% (2025) to 60% (2030). | G24: Estimate
A25: Ceiling on inference share | B25: 0.7 | E25: share | F25: Author's estimate. | G25: Estimate
A26: Share of inference capacity that serves language model tokens | B26: 0.6 | E26: share | F26: Author's estimate. A bottom up count by chip owner puts 30% to 40% of all installed AI accelerators on language model tokens (Epoch AI chip stock by owner, shares judged). 50% inference x 60% = 30%, the low end of that band. | G26: Estimate
A27: Share of time inference servers are busy, 2026 | B27: 0.4 | E27: share | F27: Lawrence Berkeley National Laboratory (December 2024): 40% (range 37.5% to 42.5%), a modelling assumption in that report, before the agent era. Used only as the starting point for the rise below, because the throughput figure already includes today's idle time. | G27: Estimate
A28: Yearly rise in utilization as batch and agent work fills quiet hours | B28: 0.03 | E28: percentage points a year | F28: Author's estimate. | G28: Estimate
A29: Ceiling on utilization | B29: 0.6 | E29: share | F29: Author's estimate. SemiAnalysis uses 60% in its revenue per gigawatt math. | G29: Estimate
A30: Yearly growth in compute needed per token (bigger models, more reasoning) | B30: 1.2 | E30: multiple a year | F30: Author's estimate, deliberately cautious. Efficiency data is for a constant model; frontier models keep growing. Range 1.0 to 1.5. The supply path efficiency multiples in section 8 are divided by this. | G30: Estimate
A31: Yearly growth in capacity additions after 2031 | B31: 0.05 | E31: per year | F31: Author's estimate for the rough extension to 2036. | G31: Estimate
A33: 5. Token mix (used only with the compute weighted unit)
A34: Cached input tokens as a share of all tokens, 2026 | B34: 0.35 | E34: share of all tokens | F34: Cached share of input tokens by provider (Requesty, April 2026): Anthropic 77.5%, OpenAI 36.4%, Gemini on Vertex 9.6%. Coding agents run above 90%. | G34: Estimate
A35: Yearly rise in cached share as agents grow | B35: 0.05 | E35: percentage points a year | F35: Author's estimate. | G35: Estimate
A36: Ceiling on cached share | B36: 0.75 | E36: share | F36: Author's estimate. | G36: Estimate
A37: New output tokens as a share of all tokens, 2026 | B37: 0.1 | E37: share of all tokens | F37: Epoch AI assumes about 11% for Google (8 to 1 input to output). | G37: Estimate
A38: Compute weight of a fresh input token | B38: 0.1 | E38: relative to an output token (= 1) | F38: Range 0.02 to 0.3. Built from measured prefill versus decode cost (arXiv 2512.01644 and 2602.05712). Price pages imply 0.2. | G38: Estimate
A39: Compute weight of a cached input token | B39: 0.02 | E39: relative to an output token (= 1) | F39: Range 0.001 to 0.03. No measurement isolates it. Price pages imply 0.02 to 0.1. Cached context still holds chip memory and slows output on long contexts (Epoch AI: output throughput falls 40x from short to very long context). | G39: Estimate
A41: 6. Squeeze line
A42: Squeeze line: load where rationing and price rises start | B42: 0.85 | E42: share of capacity | F42: Author's assumption, not a measurement. At 40% average utilization the daily peak already runs near full, so rationing starts before the average reaches 100%. A shortage is always demand above 100% of capacity. | G42: Estimate
A44: 7. Memory gate and High path slippage settings
A45: Memory gate: cap on 2027 growth in effective capacity | B45: 1 | E45: multiple of Base path growth (1 = Base) | F45: Effective capacity = GW x tokens per watt index (chips in buildings, before inference share and utilization). At 1.0 no path may grow effective capacity in 2027 faster than Base does, so it binds only on High. Base growth is already planned against committed memory. Set below 1 to make the gate bind on Base too. | G45: Estimate
A46: Memory gate: share of the 2027 shortfall still missing in 2028 | B46: 0 | E46: share (0 = full catch up in 2028) | F46: 0 means the gate only delays chips by one year. New clean rooms land in late 2028, so 0.5 is a defensible tighter test. 2029 onward is never gated. | G46: Estimate
A47: High path slippage: share of announced 2027 additions that slip | B47: 0.25 | E47: share | F47: Slippage estimates run from 25% to 35% (SynMax) up to 30% to 50% (Sightline); 25% is the low end. Applied to 2027 additions; later years compound from the lower base. | G47: Estimate
...

Sheet North America
A1: North America: token demand against token supply
A2: Every cell is a formula driven by the Inputs sheet. Tokens in trillion tokens per day; capacity in gigawatts (GW) of information technology (IT) power for AI. Columns are mid year; 2032 to 2036 are a rough extension.
A3: Year (mid year) | B3: 2026 | C3: 2027 | D3: 2028 | E3: 2029 | F3: 2030 | G3: 2031 | H3: 2032 | I3: 2033 | J3: 2034 | K3: 2035 | L3: 2036
A4: Shared drivers
A5: Inference share of AI compute (after any training shift) | B5: =MIN(Inputs!$B$25,Inputs!$B$23+Inputs!$B$24*0)-0 -> 0.5 | C5: =MIN(Inputs!$B$25,Inputs!$B$23+Inputs!$B$24*1)-Inputs!$B$9/100 -> 0.525 | D5: =MIN(Inputs!$B$25,Inputs!$B$23+Inputs!$B$24*2)-Inputs!$B$9/100 -> 0.55 | E5: =MIN(Inputs!$B$25,Inputs!$B$23+Inputs!$B$24*3)-Inputs!$B$9/100 -> 0.575 | F5: =MIN(Inputs!$B$25,Inputs!$B$23+Inputs!$B$24*4)-Inputs!$B$9/100 -> 0.6 | G5: =MIN(Inputs!$B$25,Inputs!$B$23+Inputs!$B$24*5)-Inputs!$B$9/100 -> 0.625 | H5: =MIN(Inputs!$B$25,Inputs!$B$23+Inputs!$B$24*6)-Inputs!$B$9/100 -> 0.65 | I5: =MIN(Inputs!$B$25,Inputs!$B$23+Inputs!$B$24*7)-Inputs!$B$9/100 -> 0.675 | J5: =MIN(Inputs!$B$25,Inputs!$B$23+Inputs!$B$24*8)-Inputs!$B$9/100 -> 0.7 | K5: =MIN(Inputs!$B$25,Inputs!$B$23+Inputs!$B$24*9)-Inputs!$B$9/100 -> 0.7 | L5: =MIN(Inputs!$B$25,Inputs!$B$23+Inputs!$B$24*10)-Inputs!$B$9/100 -> 0.7
A6: Utilization (share of time serving) | B6: =MIN(Inputs!$B$29,Inputs!$B$27+Inputs!$B$28*0) -> 0.4 | C6: =MIN(Inputs!$B$29,Inputs!$B$27+Inputs!$B$28*1) -> 0.43 | D6: =MIN(Inputs!$B$29,Inputs!$B$27+Inputs!$B$28*2) -> 0.46 | E6: =MIN(Inputs!$B$29,Inputs!$B$27+Inputs!$B$28*3) -> 0.49 | F6: =MIN(Inputs!$B$29,Inputs!$B$27+Inputs!$B$28*4) -> 0.52 | G6: =MIN(Inputs!$B$29,Inputs!$B$27+Inputs!$B$28*5) -> 0.55 | H6: =MIN(Inputs!$B$29,Inputs!$B$27+Inputs!$B$28*6) -> 0.58 | I6: =MIN(Inputs!$B$29,Inputs!$B$27+Inputs!$B$28*7) -> 0.6 | J6: =MIN(Inputs!$B$29,Inputs!$B$27+Inputs!$B$28*8) -> 0.6 | K6: =MIN(Inputs!$B$29,Inputs!$B$27+Inputs!$B$28*9) -> 0.6 | L6: =MIN(Inputs!$B$29,Inputs!$B$27+Inputs!$B$28*10) -> 0.6
A7: Utilization factor applied to supply (change versus 2026) | B7: =IF(Inputs!$B$12=1,B6/$B$6,B6) -> 1 | C7: =IF(Inputs!$B$12=1,C6/$B$6,C6) -> 1.075 | D7: =IF(Inputs!$B$12=1,D6/$B$6,D6) -> 1.15 | E7: =IF(Inputs!$B$12=1,E6/$B$6,E6) -> 1.225 | F7: =IF(Inputs!$B$12=1,F6/$B$6,F6) -> 1.3 | G7: =IF(Inputs!$B$12=1,G6/$B$6,G6) -> 1.375 | H7: =IF(Inputs!$B$12=1,H6/$B$6,H6) -> 1.45 | I7: =IF(Inputs!$B$12=1,I6/$B$6,I6) -> 1.5 | ... L7: =IF(Inputs!$B$12=1,L6/$B$6,L6) -> 1.5
A8: Cached input share of all tokens | B8: =MIN(Inputs!$B$36,Inputs!$B$34+Inputs!$B$35*0) -> 0.35 | C8: =MIN(Inputs!$B$36,Inputs!$B$34+Inputs!$B$35*1) -> 0.4 | D8: =MIN(Inputs!$B$36,Inputs!$B$34+Inputs!$B$35*2) -> 0.45 | E8: =MIN(Inputs!$B$36,Inputs!$B$34+Inputs!$B$35*3) -> 0.5 | F8: =MIN(Inputs!$B$36,Inputs!$B$34+Inputs!$B$35*4) -> 0.55 | G8: =MIN(Inputs!$B$36,Inputs!$B$34+Inputs!$B$35*5) -> 0.6 | H8: =MIN(Inputs!$B$36,Inputs!$B$34+Inputs!$B$35*6) -> 0.65 | I8: =MIN(Inputs!$B$36,Inputs!$B$34+Inputs!$B$35*7) -> 0.7 | J8: =MIN(Inputs!$B$36,Inputs!$B$34+Inputs!$B$35*8) -> 0.75 | K8: =MIN(Inputs!$B$36,Inputs!$B$34+Inputs!$B$35*9) -> 0.75 | L8: =MIN(Inputs!$B$36,Inputs!$B$34+Inputs!$B$35*10) -> 0.75
A9: Compute per raw token (output token = 1) | B9: =Inputs!$B$37*(1-B8)/(1-Inputs!$B$34)+(1-B8-Inputs!$B$37*(1-B8)/(1-Inputs!$B$34))*Inputs!$B$38+B8*Inputs!$B$39 -> 0.162 | C9: =Inputs!$B$37*(1-C8)/(1-Inputs!$B$34)+(1-C8-Inputs!$B$37*(1-C8)/(1-Inputs!$B$34))*Inputs!$B$38+C8*Inputs!$B$39 -> 0.15107692 | D9: =Inputs!$B$37*(1-D8)/(1-Inputs!$B$34)+(1-D8-Inputs!$B$37*(1-D8)/(1-Inputs!$B$34))*Inputs!$B$38+D8*Inputs!$B$39 -> 0.14015385 | E9: =Inputs!$B$37*(1-E8)/(1-Inputs!$B$34)+(1-E8-Inputs!$B$37*(1-E8)/(1-Inputs!$B$34))*Inputs!$B$38+E8*Inputs!$B$39 -> 0.12923077 | F9: =Inputs!$B$37*(1-F8)/(1-Inputs!$B$34)+(1-F8-Inputs!$B$37*(1-F8)/(1-Inputs!$B$34))*Inputs!$B$38+F8*Inputs!$B$39 -> 0.11830769 | G9: =Inputs!$B$37*(1-G8)/(1-Inputs!$B$34)+(1-G8-Inputs!$B$37*(1-G8)/(1-Inputs!$B$34))*Inputs!$B$38+G8*Inputs!$B$39 -> 0.10738462 | H9: =Inputs!$B$37*(1-H8)/(1-Inputs!$B$34)+(1-H8-Inputs!$B$37*(1-H8)/(1-Inputs!$B$34))*Inputs!$B$38+H8*Inputs!$B$39 -> 0.096461538 | I9: =Inputs!$B$37*(1-I8)/(1-Inputs!$B$34)+(1-I8-Inputs!$B$37*(1-I8)/(1-Inputs!$B$34))*Inputs!$B$38+I8*Inputs!$B$39 -> 0.085538462 | ... L9: =Inputs!$B$37*(1-L8)/(1-Inputs!$B$34)+(1-L8-Inputs!$B$37*(1-L8)/(1-Inputs!$B$34))*Inputs!$B$38+L8*Inputs!$B$39 -> 0.074615385
A10: Demand weighting factor versus 2026 (1 if raw tokens chosen) | B10: =IF(Inputs!$B$8=1,1,B9/$B$9) -> 1 | C10: =IF(Inputs!$B$8=1,1,C9/$B$9) -> 0.9325736 | D10: =IF(Inputs!$B$8=1,1,D9/$B$9) -> 0.8651472 | E10: =IF(Inputs!$B$8=1,1,E9/$B$9) -> 0.7977208 | F10: =IF(Inputs!$B$8=1,1,F9/$B$9) -> 0.7302944 | G10: =IF(Inputs!$B$8=1,1,G9/$B$9) -> 0.662868 | H10: =IF(Inputs!$B$8=1,1,H9/$B$9) -> 0.5954416 | I10: =IF(Inputs!$B$8=1,1,I9/$B$9) -> 0.52801519 | ... L10: =IF(Inputs!$B$8=1,1,L9/$B$9) -> 0.46058879
A11: Low supply path
A12: Gigawatts added in the year | B12: 0 | C12: =Inputs!$B$51 -> 6 | D12: =C12*(1+Inputs!$B$52) -> 6.3 | E12: =D12*(1+Inputs!$B$52) -> 6.615 | F12: =E12*(1+Inputs!$B$52) -> 6.94575 | G12: =F12*(1+Inputs!$B$52) -> 7.2930375 | H12: =G12*(1+Inputs!$B$31) -> 7.6576894 | I12: =H12*(1+Inputs!$B$31) -> 8.0405738 | J12: =I12*(1+Inputs!$B$31) -> 8.4426025 | K12: =J12*(1+Inputs!$B$31) -> 8.8647327 | L12: =K12*(1+Inputs!$B$31) -> 9.3079693
A13: AI capacity in operation, GW | B13: =Inputs!$B$19 -> 15 | C13: =B13+C12 -> 21 | D13: =C13+D12 -> 27.3 | E13: =D13+E12 -> 33.915 | F13: =E13+F12 -> 40.86075 | G13: =F13+G12 -> 48.153787 | H13: =G13+H12 -> 55.811477 | I13: =H13+I12 -> 63.852051 | J13: =I13+J12 -> 72.294653 | ... L13: =K13+L12 -> 90.467355
A14: Tokens per watt index (2026 = 1), net of bigger models | B14: 1 | C14: =B14*MAX(Inputs!$B$55,Inputs!$B$53*Inputs!$B$54^0)/Inputs!$B$30 -> 1.2083333 | D14: =C14*MAX(Inputs!$B$55,Inputs!$B$53*Inputs!$B$54^1)/Inputs!$B$30 -> 1.4600694 | E14: =D14*MAX(Inputs!$B$55,Inputs!$B$53*Inputs!$B$54^2)/Inputs!$B$30 -> 1.7642506 | F14: =E14*MAX(Inputs!$B$55,Inputs!$B$53*Inputs!$B$54^3)/Inputs!$B$30 -> 2.1318028 | G14: =F14*MAX(Inputs!$B$55,Inputs!$B$53*Inputs!$B$54^4)/Inputs!$B$30 -> 2.5759284 | H14: =G14*MAX(Inputs!$B$55,Inputs!$B$53*Inputs!$B$54^5)/Inputs!$B$30 -> 3.1125801 | I14: =H14*MAX(Inputs!$B$55,Inputs!$B$53*Inputs!$B$54^6)/Inputs!$B$30 -> 3.7610343 | J14: =I14*MAX(Inputs!$B$55,Inputs!$B$53*Inputs!$B$54^7)/Inputs!$B$30 -> 4.5445831 | K14: =J14*MAX(Inputs!$B$55,Inputs!$B$53*Inputs!$B$54^8)/Inputs!$B$30 -> 5.4913713 | L14: =K14*MAX(Inputs!$B$55,Inputs!$B$53*Inputs!$B$54^9)/Inputs!$B$30 -> 6.6354069
A15: Supply, Low path (trillion tokens per day) | B15: =B13*1000*B5*Inputs!$B$26*B7*Inputs!$B$20*86400/1000000*B14*B52 -> 311.04 | C15: =C13*1000*C5*Inputs!$B$26*C7*Inputs!$B$20*86400/1000000*C14*C52 -> 593.92116 | D15: =D13*1000*D5*Inputs!$B$26*D7*Inputs!$B$20*86400/1000000*D14*D52 -> 1045.5665 | E15: =E13*1000*E5*Inputs!$B$26*E7*Inputs!$B$20*86400/1000000*E14*E52 -> 1747.8775 | F15: =F13*1000*F5*Inputs!$B$26*F7*Inputs!$B$20*86400/1000000*F14*F52 -> 2817.7531 | G15: =G13*1000*G5*Inputs!$B$26*G7*Inputs!$B$20*86400/1000000*G14*G52 -> 4420.8108 | H15: =H13*1000*H5*Inputs!$B$26*H7*Inputs!$B$20*86400/1000000*H14*H52 -> 6790.166 | I15: =I13*1000*I5*Inputs!$B$26*I7*Inputs!$B$20*86400/1000000*I14*I52 -> 10083.984 | ... L15: =L13*1000*L5*Inputs!$B$26*L7*Inputs!$B$20*86400/1000000*L14*L52 -> 26139.889
A16: Base supply path
A17: Gigawatts added in the year | B17: 0 | C17: =Inputs!$C$51 -> 12 | D17: =C17*(1+Inputs!$C$52) -> 14.64 | E17: =D17*(1+Inputs!$C$52) -> 17.8608 | F17: =E17*(1+Inputs!$C$52) -> 21.790176 | G17: =F17*(1+Inputs!$C$52) -> 26.584015 | H17: =G17*(1+Inputs!$B$31) -> 27.913215 | I17: =H17*(1+Inputs!$B$31) -> 29.308876 | J17: =I17*(1+Inputs!$B$31) -> 30.77432 | K17: =J17*(1+Inputs!$B$31) -> 32.313036 | L17: =K17*(1+Inputs!$B$31) -> 33.928688
A18: AI capacity in operation, GW | B18: =Inputs!$B$19 -> 15 | C18: =B18+C17 -> 27 | D18: =C18+D17 -> 41.64 | E18: =D18+E17 -> 59.5008 | F18: =E18+F17 -> 81.290976 | G18: =F18+G17 -> 107.87499 | H18: =G18+H17 -> 135.78821 | I18: =H18+I17 -> 165.09708 | J18: =I18+J17 -> 195.8714 | ... L18: =K18+L17 -> 262.11313
A19: Tokens per watt index (2026 = 1), net of bigger models | B19: 1 | C19: =B19*MAX(Inputs!$C$55,Inputs!$C$53*Inputs!$C$54^0)/Inputs!$B$30 -> 1.7 | D19: =C19*MAX(Inputs!$C$55,Inputs!$C$53*Inputs!$C$54^1)/Inputs!$B$30 -> 2.4565 | E19: =D19*MAX(Inputs!$C$55,Inputs!$C$53*Inputs!$C$54^2)/Inputs!$B$30 -> 3.070625 | F19: =E19*MAX(Inputs!$C$55,Inputs!$C$53*Inputs!$C$54^3)/Inputs!$B$30 -> 3.8382813 | G19: =F19*MAX(Inputs!$C$55,Inputs!$C$53*Inputs!$C$54^4)/Inputs!$B$30 -> 4.7978516 | H19: =G19*MAX(Inputs!$C$55,Inputs!$C$53*Inputs!$C$54^5)/Inputs!$B$30 -> 5.9973145 | I19: =H19*MAX(Inputs!$C$55,Inputs!$C$53*Inputs!$C$54^6)/Inputs!$B$30 -> 7.4966431 | J19: =I19*MAX(Inputs!$C$55,Inputs!$C$53*Inputs!$C$54^7)/Inputs!$B$30 -> 9.3708038 | K19: =J19*MAX(Inputs!$C$55,Inputs!$C$53*Inputs!$C$54^8)/Inputs!$B$30 -> 11.713505 | L19: =K19*MAX(Inputs!$C$55,Inputs!$C$53*Inputs!$C$54^9)/Inputs!$B$30 -> 14.641881
A20: Supply, Base path (trillion tokens per day) | B20: =B18*1000*B5*Inputs!$B$26*B7*Inputs!$B$20*86400/1000000*B19*B53 -> 311.04 | C20: =C18*1000*C5*Inputs!$B$26*C7*Inputs!$B$20*86400/1000000*C19*C53 -> 1074.3244 | D20: =D18*1000*D5*Inputs!$B$26*D7*Inputs!$B$20*86400/1000000*D19*D53 -> 2683.1379 | E20: =E18*1000*E5*Inputs!$B$26*E7*Inputs!$B$20*86400/1000000*E19*E53 -> 5337.1388 | F20: =F18*1000*F5*Inputs!$B$26*F7*Inputs!$B$20*86400/1000000*F19*F53 -> 10093.196 | G20: =G18*1000*G5*Inputs!$B$26*G7*Inputs!$B$20*86400/1000000*G19*G53 -> 18446.13 | H20: =H18*1000*H5*Inputs!$B$26*H7*Inputs!$B$20*86400/1000000*H19*H53 -> 31831.361 | I20: =I18*1000*I5*Inputs!$B$26*I7*Inputs!$B$20*86400/1000000*I19*I53 -> 51970.422 | ... L20: =L18*1000*L5*Inputs!$B$26*L7*Inputs!$B$20*86400/1000000*L19*L53 -> 167120.58
A21: High supply path
A22: Gigawatts added in the year | B22: 0 | C22: =Inputs!$D$51*(1-IF(Inputs!$B$11=1,Inputs!$B$47,0)) -> 15 | D22: =C22*(1+Inputs!$D$52) -> 21 | E22: =D22*(1+Inputs!$D$52) -> 29.4 | F22: =E22*(1+Inputs!$D$52) -> 41.16 | G22: =F22*(1+Inputs!$D$52) -> 57.624 | H22: =G22*(1+Inputs!$B$31) -> 60.5052 | I22: =H22*(1+Inputs!$B$31) -> 63.53046 | J22: =I22*(1+Inputs!$B$31) -> 66.706983 | K22: =J22*(1+Inputs!$B$31) -> 70.042332 | L22: =K22*(1+Inputs!$B$31) -> 73.544449
A23: AI capacity in operation, GW | B23: =Inputs!$B$19 -> 15 | C23: =B23+C22 -> 30 | D23: =C23+D22 -> 51 | E23: =D23+E22 -> 80.4 | F23: =E23+F22 -> 121.56 | G23: =F23+G22 -> 179.184 | H23: =G23+H22 -> 239.6892 | I23: =H23+I22 -> 303.21966 | J23: =I23+J22 -> 369.92664 | ... L23: =K23+L22 -> 513.51342
A24: Tokens per watt index (2026 = 1), net of bigger models | B24: 1 | C24: =B24*MAX(Inputs!$D$55,Inputs!$D$53*Inputs!$D$54^0)/Inputs!$B$30 -> 2.75 | D24: =C24*MAX(Inputs!$D$55,Inputs!$D$53*Inputs!$D$54^1)/Inputs!$B$30 -> 6.428125 | E24: =D24*MAX(Inputs!$D$55,Inputs!$D$53*Inputs!$D$54^2)/Inputs!$B$30 -> 12.771881 | F24: =E24*MAX(Inputs!$D$55,Inputs!$D$53*Inputs!$D$54^3)/Inputs!$B$30 -> 21.569711 | G24: =F24*MAX(Inputs!$D$55,Inputs!$D$53*Inputs!$D$54^4)/Inputs!$B$30 -> 35.949519 | H24: =G24*MAX(Inputs!$D$55,Inputs!$D$53*Inputs!$D$54^5)/Inputs!$B$30 -> 59.915864 | I24: =H24*MAX(Inputs!$D$55,Inputs!$D$53*Inputs!$D$54^6)/Inputs!$B$30 -> 99.859774 | J24: =I24*MAX(Inputs!$D$55,Inputs!$D$53*Inputs!$D$54^7)/Inputs!$B$30 -> 166.43296 | K24: =J24*MAX(Inputs!$D$55,Inputs!$D$53*Inputs!$D$54^8)/Inputs!$B$30 -> 277.38826 | L24: =K24*MAX(Inputs!$D$55,Inputs!$D$53*Inputs!$D$54^9)/Inputs!$B$30 -> 462.31377
A25: Supply, High path (trillion tokens per day) | B25: =B23*1000*B5*Inputs!$B$26*B7*Inputs!$B$20*86400/1000000*B24*B54 -> 311.04 | C25: =C23*1000*C5*Inputs!$B$26*C7*Inputs!$B$20*86400/1000000*C24*C54 -> 1074.3244 | D25: =D23*1000*D5*Inputs!$B$26*D7*Inputs!$B$20*86400/1000000*D24*D54 -> 8599.4366 | E25: =E23*1000*E5*Inputs!$B$26*E7*Inputs!$B$20*86400/1000000*E24*E54 -> 29996.447 | F25: =F23*1000*F5*Inputs!$B$26*F7*Inputs!$B$20*86400/1000000*F24*F54 -> 84817.331 | G25: =G23*1000*G5*Inputs!$B$26*G7*Inputs!$B$20*86400/1000000*G24*G54 -> 229577.86 | H25: =H23*1000*H5*Inputs!$B$26*H7*Inputs!$B$20*86400/1000000*H24*H54 -> 561340.83 | I25: =I23*1000*I5*Inputs!$B$26*I7*Inputs!$B$20*86400/1000000*I24*I54 -> 1271446.1 | ... L25: =L23*1000*L5*Inputs!$B$26*L7*Inputs!$B$20*86400/1000000*L24*L54 -> 10337914
A26: Demand paths (trillion tokens per day, in the unit chosen on Inputs)
A27: Demand, S1 Early cloud pace | B27: =Inputs!$B$16*Inputs!$B$15 -> 187.5 | C27: =B27*(1+Inputs!$B$60/(1+Inputs!$C$60*MAX(0,1-Inputs!$D$60)))*C10/B10 -> 297.25783 | D27: =C27*(1+Inputs!$B$60/(1+Inputs!$C$60*MAX(0,2-Inputs!$D$60)))*D10/C10 -> 396.41315 | E27: =D27*(1+Inputs!$B$60/(1+Inputs!$C$60*MAX(0,3-Inputs!$D$60)))*E10/D10 -> 481.8194 | F27: =E27*(1+Inputs!$B$60/(1+Inputs!$C$60*MAX(0,4-Inputs!$D$60)))*F10/E10 -> 551.36773 | G27: =F27*(1+Inputs!$B$60/(1+Inputs!$C$60*MAX(0,5-Inputs!$D$60)))*G10/F10 -> 603.49735 | H27: =G27*(1+Inputs!$B$60/(1+Inputs!$C$60*MAX(0,6-Inputs!$D$60)))*H10/G10 -> 636.97935 | I27: =H27*(1+Inputs!$B$60/(1+Inputs!$C$60*MAX(0,7-Inputs!$D$60)))*I10/H10 -> 650.80464 | J27: =I27*(1+Inputs!$B$60/(1+Inputs!$C$60*MAX(0,8-Inputs!$D$60)))*J10/I10 -> 644.11922 | K27: =J27*(1+Inputs!$B$60/(1+Inputs!$C$60*MAX(0,9-Inputs!$D$60)))*K10/J10 -> 721.85774 | L27: =K27*(1+Inputs!$B$60/(1+Inputs!$C$60*MAX(0,10-Inputs!$D$60)))*L10/K10 -> 800.81093
A28: Demand, S2 Internet after 2001 | B28: =Inputs!$B$16*Inputs!$B$15 -> 187.5 | C28: =B28*(1+Inputs!$B$61/(1+Inputs!$C$61*MAX(0,1-Inputs!$D$61)))*C10/B10 -> 349.7151 | D28: =C28*(1+Inputs!$B$61/(1+Inputs!$C$61*MAX(0,2-Inputs!$D$61)))*D10/C10 -> 573.99189 | E28: =D28*(1+Inputs!$B$61/(1+Inputs!$C$61*MAX(0,3-Inputs!$D$61)))*E10/D10 -> 860.04273 | F28: =E28*(1+Inputs!$B$61/(1+Inputs!$C$61*MAX(0,4-Inputs!$D$61)))*F10/E10 -> 1201.7427 | G28: =F28*(1+Inputs!$B$61/(1+Inputs!$C$61*MAX(0,5-Inputs!$D$61)))*G10/F10 -> 1586.6015 | H28: =G28*(1+Inputs!$B$61/(1+Inputs!$C$61*MAX(0,6-Inputs!$D$61)))*H10/G10 -> 1995.2991 | I28: =H28*(1+Inputs!$B$61/(1+Inputs!$C$61*MAX(0,7-Inputs!$D$61)))*I10/H10 -> 2401.2691 | J28: =I28*(1+Inputs!$B$61/(1+Inputs!$C$61*MAX(0,8-Inputs!$D$61)))*J10/I10 -> 2770.32 | K28: =J28*(1+Inputs!$B$61/(1+Inputs!$C$61*MAX(0,9-Inputs!$D$61)))*K10/J10 -> 3585.12 | L28: =K28*(1+Inputs!$B$61/(1+Inputs!$C$61*MAX(0,10-Inputs!$D$61)))*L10/K10 -> 4554.0714
A29: Demand, S3 Mobile data | B29: =Inputs!$B$16*Inputs!$B$15 -> 187.5 | C29: =B29*(1+Inputs!$B$62/(1+Inputs!$C$62*MAX(0,1-Inputs!$D$62)))*C10/B10 -> 472.11538 | D29: =C29*(1+Inputs!$B$62/(1+Inputs!$C$62*MAX(0,2-Inputs!$D$62)))*D10/C10 -> 903.33534 | E29: =D29*(1+Inputs!$B$62/(1+Inputs!$C$62*MAX(0,3-Inputs!$D$62)))*E10/D10 -> 1476.5625 | F29: =E29*(1+Inputs!$B$62/(1+Inputs!$C$62*MAX(0,4-Inputs!$D$62)))*F10/E10 -> 2172.4679 | G29: =F29*(1+Inputs!$B$62/(1+Inputs!$C$62*MAX(0,5-Inputs!$D$62)))*G10/F10 -> 2957.8334 | H29: =G29*(1+Inputs!$B$62/(1+Inputs!$C$62*MAX(0,6-Inputs!$D$62)))*H10/G10 -> 3786.1751 | I29: =H29*(1+Inputs!$B$62/(1+Inputs!$C$62*MAX(0,7-Inputs!$D$62)))*I10/H10 -> 4598.2297 | J29: =I29*(1+Inputs!$B$62/(1+Inputs!$C$62*MAX(0,8-Inputs!$D$62)))*J10/I10 -> 5322.3491 | K29: =J29*(1+Inputs!$B$62/(1+Inputs!$C$62*MAX(0,9-Inputs!$D$62)))*K10/J10 -> 6882.348 | L29: =K29*(1+Inputs!$B$62/(1+Inputs!$C$62*MAX(0,10-Inputs!$D$62)))*L10/K10 -> 8710.4717
A30: Demand, S4 Today's pace, then fading (headline) | B30: =Inputs!$B$16*Inputs!$B$15 -> 187.5 | C30: =B30*(1+Inputs!$B$63/(1+Inputs!$C$63*MAX(0,1-Inputs!$D$63)))*C10/B10 -> 699.4302 | D30: =C30*(1+Inputs!$B$63/(1+Inputs!$C$63*MAX(0,2-Inputs!$D$63)))*D10/C10 -> 1793.9082 | E30: =D30*(1+Inputs!$B$63/(1+Inputs!$C$63*MAX(0,3-Inputs!$D$63)))*E10/D10 -> 3721.7195 | F30: =E30*(1+Inputs!$B$63/(1+Inputs!$C$63*MAX(0,4-Inputs!$D$63)))*F10/E10 -> 6704.3832 | G30: =F30*(1+Inputs!$B$63/(1+Inputs!$C$63*MAX(0,5-Inputs!$D$63)))*G10/F10 -> 10889.633 | H30: =G30*(1+Inputs!$B$63/(1+Inputs!$C$63*MAX(0,6-Inputs!$D$63)))*H10/G10 -> 16303.246 | I30: =H30*(1+Inputs!$B$63/(1+Inputs!$C$63*MAX(0,7-Inputs!$D$63)))*I10/H10 -> 22797.743 | J30: =I30*(1+Inputs!$B$63/(1+Inputs!$C$63*MAX(0,8-Inputs!$D$63)))*J10/I10 -> 29998.311 | K30: =J30*(1+Inputs!$B$63/(1+Inputs!$C$63*MAX(0,9-Inputs!$D$63)))*K10/J10 -> 43633.906 | L30: =K30*(1+Inputs!$B$63/(1+Inputs!$C$63*MAX(0,10-Inputs!$D$63)))*L10/K10 -> 61565.648
A31: Demand, S8 Acceleration, then fading | B31: =Inputs!$B$16*Inputs!$B$15 -> 187.5 | C31: =B31*(1+Inputs!$B$64/(1+Inputs!$C$64*MAX(0,1-Inputs!$D$64)))*C10/B10 -> 874.28775 | D31: =C31*(1+Inputs!$B$64/(1+Inputs!$C$64*MAX(0,2-Inputs!$D$64)))*D10/C10 -> 2719.4884 | E31: =D31*(1+Inputs!$B$64/(1+Inputs!$C$64*MAX(0,3-Inputs!$D$64)))*E10/D10 -> 6686.7773 | F31: =E31*(1+Inputs!$B$64/(1+Inputs!$C$64*MAX(0,4-Inputs!$D$64)))*F10/E10 -> 14020.405 | G31: =F31*(1+Inputs!$B$64/(1+Inputs!$C$64*MAX(0,5-Inputs!$D$64)))*G10/F10 -> 26121.653 | H31: =G31*(1+Inputs!$B$64/(1+Inputs!$C$64*MAX(0,6-Inputs!$D$64)))*H10/G10 -> 44321.983 | I31: =H31*(1+Inputs!$B$64/(1+Inputs!$C$64*MAX(0,7-Inputs!$D$64)))*I10/H10 -> 69536.195 | J31: =I31*(1+Inputs!$B$64/(1+Inputs!$C$64*MAX(0,8-Inputs!$D$64)))*J10/I10 -> 101779.67 | K31: =J31*(1+Inputs!$B$64/(1+Inputs!$C$64*MAX(0,9-Inputs!$D$64)))*K10/J10 -> 163464.32 | L31: =K31*(1+Inputs!$B$64/(1+Inputs!$C$64*MAX(0,10-Inputs!$D$64)))*L10/K10 -> 253033.81
A32: Demand, S5 Last year's pace returns | B32: =Inputs!$B$16*Inputs!$B$15 -> 187.5 | C32: =B32*(1+Inputs!$B$65/(1+Inputs!$C$65*MAX(0,1-Inputs!$D$65)))*C10/B10 -> 1224.0028 | D32: =C32*(1+Inputs!$B$65/(1+Inputs!$C$65*MAX(0,2-Inputs!$D$65)))*D10/C10 -> 4542.0228 | E32: =D32*(1+Inputs!$B$65/(1+Inputs!$C$65*MAX(0,3-Inputs!$D$65)))*E10/D10 -> 12564.103 | F32: =E32*(1+Inputs!$B$65/(1+Inputs!$C$65*MAX(0,4-Inputs!$D$65)))*F10/E10 -> 28755.342 | G32: =F32*(1+Inputs!$B$65/(1+Inputs!$C$65*MAX(0,5-Inputs!$D$65)))*G10/F10 -> 57420.94 | H32: =G32*(1+Inputs!$B$65/(1+Inputs!$C$65*MAX(0,6-Inputs!$D$65)))*H10/G10 -> 103160.26 | I32: =H32*(1+Inputs!$B$65/(1+Inputs!$C$65*MAX(0,7-Inputs!$D$65)))*I10/H10 -> 169888.89 | J32: =I32*(1+Inputs!$B$65/(1+Inputs!$C$65*MAX(0,8-Inputs!$D$65)))*J10/I10 -> 259340.28 | K32: =J32*(1+Inputs!$B$65/(1+Inputs!$C$65*MAX(0,9-Inputs!$D$65)))*K10/J10 -> 432233.8 | L32: =K32*(1+Inputs!$B$65/(1+Inputs!$C$65*MAX(0,10-Inputs!$D$65)))*L10/K10 -> 691574.07
A33: Demand, S6 Today's pace for three years | B33: =Inputs!$B$16*Inputs!$B$15 -> 187.5 | C33: =B33*(1+Inputs!$B$66/(1+Inputs!$C$66*MAX(0,1-Inputs!$D$66)))*C10/B10 -> 699.4302 | D33: =C33*(1+Inputs!$B$66/(1+Inputs!$C$66*MAX(0,2-Inputs!$D$66)))*D10/C10 -> 2595.4416 | E33: =D33*(1+Inputs!$B$66/(1+Inputs!$C$66*MAX(0,3-Inputs!$D$66)))*E10/D10 -> 9572.6496 | F33: =E33*(1+Inputs!$B$66/(1+Inputs!$C$66*MAX(0,4-Inputs!$D$66)))*F10/E10 -> 24228.591 | G33: =F33*(1+Inputs!$B$66/(1+Inputs!$C$66*MAX(0,5-Inputs!$D$66)))*G10/F10 -> 49481.146 | H33: =G33*(1+Inputs!$B$66/(1+Inputs!$C$66*MAX(0,6-Inputs!$D$66)))*H10/G10 -> 87462.122 | I33: =H33*(1+Inputs!$B$66/(1+Inputs!$C$66*MAX(0,7-Inputs!$D$66)))*I10/H10 -> 138788.21 | J33: =I33*(1+Inputs!$B$66/(1+Inputs!$C$66*MAX(0,8-Inputs!$D$66)))*J10/I10 -> 201775.43 | K33: =J33*(1+Inputs!$B$66/(1+Inputs!$C$66*MAX(0,9-Inputs!$D$66)))*K10/J10 -> 318184.33 | L33: =K33*(1+Inputs!$B$66/(1+Inputs!$C$66*MAX(0,10-Inputs!$D$66)))*L10/K10 -> 479972.97
A34: Demand, S7 Demand falls | B34: =Inputs!$B$16*Inputs!$B$15 -> 187.5 | C34: =B34*(1+Inputs!$B$67/(1+Inputs!$C$67*MAX(0,1-Inputs!$D$67)))*C10/B10 -> 131.14316 | D34: =C34*(1+Inputs!$B$67/(1+Inputs!$C$67*MAX(0,2-Inputs!$D$67)))*D10/C10 -> 114.05749 | E34: =D34*(1+Inputs!$B$67/(1+Inputs!$C$67*MAX(0,3-Inputs!$D$67)))*E10/D10 -> 101.41226 | F34: =E34*(1+Inputs!$B$67/(1+Inputs!$C$67*MAX(0,4-Inputs!$D$67)))*F10/E10 -> 90.519496 | G34: =F34*(1+Inputs!$B$67/(1+Inputs!$C$67*MAX(0,5-Inputs!$D$67)))*G10/F10 -> 80.582 | H34: =G34*(1+Inputs!$B$67/(1+Inputs!$C$67*MAX(0,6-Inputs!$D$67)))*H10/G10 -> 71.254244 | I34: =H34*(1+Inputs!$B$67/(1+Inputs!$C$67*MAX(0,7-Inputs!$D$67)))*I10/H10 -> 62.354193 | J34: =I34*(1+Inputs!$B$67/(1+Inputs!$C$67*MAX(0,8-Inputs!$D$67)))*J10/I10 -> 53.773609 | K34: =J34*(1+Inputs!$B$67/(1+Inputs!$C$67*MAX(0,9-Inputs!$D$67)))*K10/J10 -> 53.235873 | L34: =K34*(1+Inputs!$B$67/(1+Inputs!$C$67*MAX(0,10-Inputs!$D$67)))*L10/K10 -> 52.760553
A35: Supply path chosen on Inputs (section 1)
A36: Supply, chosen path (trillion tokens per day) | B36: =CHOOSE(Inputs!$B$7,B15,B20,B25) -> 311.04 | C36: =CHOOSE(Inputs!$B$7,C15,C20,C25) -> 1074.3244 | D36: =CHOOSE(Inputs!$B$7,D15,D20,D25) -> 2683.1379 | E36: =CHOOSE(Inputs!$B$7,E15,E20,E25) -> 5337.1388 | F36: =CHOOSE(Inputs!$B$7,F15,F20,F25) -> 10093.196 | G36: =CHOOSE(Inputs!$B$7,G15,G20,G25) -> 18446.13 | H36: =CHOOSE(Inputs!$B$7,H15,H20,H25) -> 31831.361 | I36: =CHOOSE(Inputs!$B$7,I15,I20,I25) -> 51970.422 | ... L36: =CHOOSE(Inputs!$B$7,L15,L20,L25) -> 167120.58
A37: Load: demand as a share of the chosen supply path (squeeze line on Inputs; 100% or more = shortage)
A38: Load, S1 Early cloud pace | B38: =B27/B36 -> 0.60281636 | C38: =C27/C36 -> 0.27669281 | D38: =D27/D36 -> 0.14774237 | E38: =E27/E36 -> 0.090276722 | F38: =F27/F36 -> 0.054627664 | G38: =G27/G36 -> 0.032716745 | H38: =H27/H36 -> 0.020011062 | I38: =I27/I36 -> 0.012522597 | ... L38: =L27/L36 -> 0.0047918153
A39: Load, S2 Internet after 2001 | B39: =B28/B36 -> 0.60281636 | C39: =C28/C36 -> 0.32552096 | D39: =D28/D36 -> 0.2139256 | E39: =E28/E36 -> 0.16114303 | F39: =F28/F36 -> 0.11906463 | G39: =G28/G36 -> 0.086012702 | H39: =H28/H36 -> 0.062683438 | I39: =I28/I36 -> 0.046204533 | ... L39: =L28/L36 -> 0.027250214
A40: Load, S3 Mobile data | B40: =B29/B36 -> 0.60281636 | C40: =C29/C36 -> 0.43945329 | D40: =D29/D36 -> 0.33667123 | E40: =E29/E36 -> 0.27665806 | F40: =F29/F36 -> 0.21524083 | G40: =G29/G36 -> 0.16034981 | H40: =H29/H36 -> 0.11894481 | I40: =I29/I36 -> 0.088477821 | ... L40: =L29/L36 -> 0.052120881
...

Sheet Matrix
A1: Matrix: first year each demand and supply pairing reaches a squeeze or a shortage
A2: Shortage = demand above 100% of capacity. Squeeze = demand above the squeeze line on Inputs (85% by default), first tested in 2027. 'None by 2036' means supply stays ahead through the whole horizon.
A4: North America: first shortage year
A5: Demand path | B5: Low supply | C5: Base supply | D5: High supply
A6: S1 Early cloud pace | B6: =IF(MIN('North America'!$B$57:$L$57)=9999,"None by 2036",MIN('North America'!$B$57:$L$57)) -> None by 2036 | C6: =IF(MIN('North America'!$B$73:$L$73)=9999,"None by 2036",MIN('North America'!$B$73:$L$73)) -> None by 2036 | D6: =IF(MIN('North America'!$B$89:$L$89)=9999,"None by 2036",MIN('North America'!$B$89:$L$89)) -> None by 2036
A7: S2 Internet after 2001 | B7: =IF(MIN('North America'!$B$59:$L$59)=9999,"None by 2036",MIN('North America'!$B$59:$L$59)) -> None by 2036 | C7: =IF(MIN('North America'!$B$75:$L$75)=9999,"None by 2036",MIN('North America'!$B$75:$L$75)) -> None by 2036 | D7: =IF(MIN('North America'!$B$91:$L$91)=9999,"None by 2036",MIN('North America'!$B$91:$L$91)) -> None by 2036
A8: S3 Mobile data | B8: =IF(MIN('North America'!$B$61:$L$61)=9999,"None by 2036",MIN('North America'!$B$61:$L$61)) -> None by 2036 | C8: =IF(MIN('North America'!$B$77:$L$77)=9999,"None by 2036",MIN('North America'!$B$77:$L$77)) -> None by 2036 | D8: =IF(MIN('North America'!$B$93:$L$93)=9999,"None by 2036",MIN('North America'!$B$93:$L$93)) -> None by 2036
A9: S4 Today's pace, then fading (headline) | B9: =IF(MIN('North America'!$B$63:$L$63)=9999,"None by 2036",MIN('North America'!$B$63:$L$63)) -> 2027 | C9: =IF(MIN('North America'!$B$79:$L$79)=9999,"None by 2036",MIN('North America'!$B$79:$L$79)) -> None by 2036 | D9: =IF(MIN('North America'!$B$95:$L$95)=9999,"None by 2036",MIN('North America'!$B$95:$L$95)) -> None by 2036
A10: S8 Acceleration, then fading | B10: =IF(MIN('North America'!$B$65:$L$65)=9999,"None by 2036",MIN('North America'!$B$65:$L$65)) -> 2027 | C10: =IF(MIN('North America'!$B$81:$L$81)=9999,"None by 2036",MIN('North America'!$B$81:$L$81)) -> 2028 | D10: =IF(MIN('North America'!$B$97:$L$97)=9999,"None by 2036",MIN('North America'!$B$97:$L$97)) -> None by 2036
A11: S5 Last year's pace returns | B11: =IF(MIN('North America'!$B$67:$L$67)=9999,"None by 2036",MIN('North America'!$B$67:$L$67)) -> 2027 | C11: =IF(MIN('North America'!$B$83:$L$83)=9999,"None by 2036",MIN('North America'!$B$83:$L$83)) -> 2027 | D11: =IF(MIN('North America'!$B$99:$L$99)=9999,"None by 2036",MIN('North America'!$B$99:$L$99)) -> 2027
A12: S6 Today's pace for three years | B12: =IF(MIN('North America'!$B$69:$L$69)=9999,"None by 2036",MIN('North America'!$B$69:$L$69)) -> 2027 | C12: =IF(MIN('North America'!$B$85:$L$85)=9999,"None by 2036",MIN('North America'!$B$85:$L$85)) -> 2029 | D12: =IF(MIN('North America'!$B$101:$L$101)=9999,"None by 2036",MIN('North America'!$B$101:$L$101)) -> None by 2036
A13: S7 Demand falls | B13: =IF(MIN('North America'!$B$71:$L$71)=9999,"None by 2036",MIN('North America'!$B$71:$L$71)) -> None by 2036 | C13: =IF(MIN('North America'!$B$87:$L$87)=9999,"None by 2036",MIN('North America'!$B$87:$L$87)) -> None by 2036 | D13: =IF(MIN('North America'!$B$103:$L$103)=9999,"None by 2036",MIN('North America'!$B$103:$L$103)) -> None by 2036
A15: North America: first squeeze year
A16: Demand path | B16: Low supply | C16: Base supply | D16: High supply
A17: S1 Early cloud pace | B17: =IF(MIN('North America'!$B$58:$L$58)=9999,"None by 2036",MIN('North America'!$B$58:$L$58)) -> None by 2036 | C17: =IF(MIN('North America'!$B$74:$L$74)=9999,"None by 2036",MIN('North America'!$B$74:$L$74)) -> None by 2036 | D17: =IF(MIN('North America'!$B$90:$L$90)=9999,"None by 2036",MIN('North America'!$B$90:$L$90)) -> None by 2036
A18: S2 Internet after 2001 | B18: =IF(MIN('North America'!$B$60:$L$60)=9999,"None by 2036",MIN('North America'!$B$60:$L$60)) -> None by 2036 | C18: =IF(MIN('North America'!$B$76:$L$76)=9999,"None by 2036",MIN('North America'!$B$76:$L$76)) -> None by 2036 | D18: =IF(MIN('North America'!$B$92:$L$92)=9999,"None by 2036",MIN('North America'!$B$92:$L$92)) -> None by 2036
A19: S3 Mobile data | B19: =IF(MIN('North America'!$B$62:$L$62)=9999,"None by 2036",MIN('North America'!$B$62:$L$62)) -> 2028 | C19: =IF(MIN('North America'!$B$78:$L$78)=9999,"None by 2036",MIN('North America'!$B$78:$L$78)) -> None by 2036 | D19: =IF(MIN('North America'!$B$94:$L$94)=9999,"None by 2036",MIN('North America'!$B$94:$L$94)) -> None by 2036
A20: S4 Today's pace, then fading (headline) | B20: =IF(MIN('North America'!$B$64:$L$64)=9999,"None by 2036",MIN('North America'!$B$64:$L$64)) -> 2027 | C20: =IF(MIN('North America'!$B$80:$L$80)=9999,"None by 2036",MIN('North America'!$B$80:$L$80)) -> None by 2036 | D20: =IF(MIN('North America'!$B$96:$L$96)=9999,"None by 2036",MIN('North America'!$B$96:$L$96)) -> None by 2036
A21: S8 Acceleration, then fading | B21: =IF(MIN('North America'!$B$66:$L$66)=9999,"None by 2036",MIN('North America'!$B$66:$L$66)) -> 2027 | C21: =IF(MIN('North America'!$B$82:$L$82)=9999,"None by 2036",MIN('North America'!$B$82:$L$82)) -> 2028 | D21: =IF(MIN('North America'!$B$98:$L$98)=9999,"None by 2036",MIN('North America'!$B$98:$L$98)) -> None by 2036
A22: S5 Last year's pace returns | B22: =IF(MIN('North America'!$B$68:$L$68)=9999,"None by 2036",MIN('North America'!$B$68:$L$68)) -> 2027 | C22: =IF(MIN('North America'!$B$84:$L$84)=9999,"None by 2036",MIN('North America'!$B$84:$L$84)) -> 2027 | D22: =IF(MIN('North America'!$B$100:$L$100)=9999,"None by 2036",MIN('North America'!$B$100:$L$100)) -> 2027
A23: S6 Today's pace for three years | B23: =IF(MIN('North America'!$B$70:$L$70)=9999,"None by 2036",MIN('North America'!$B$70:$L$70)) -> 2027 | C23: =IF(MIN('North America'!$B$86:$L$86)=9999,"None by 2036",MIN('North America'!$B$86:$L$86)) -> 2028 | D23: =IF(MIN('North America'!$B$102:$L$102)=9999,"None by 2036",MIN('North America'!$B$102:$L$102)) -> None by 2036

Sheet Odds
A1: Odds: how much of the weighted scenario space reaches a squeeze or a shortage
A2: Each of the 24 pairings (8 demand paths x 3 supply paths) gets a weight of demand weight x supply weight (Inputs section 10). The odds are the weighted share of pairings whose first squeeze or shortage year on the Matrix sheet falls in or before the horizon year. These are judgments built on judgments: read them as how much of the scenario space ends in a squeeze, not as a forecast.
A4: Main horizon (Inputs section 10) | B4: North America
A5: ="Shortage (demand above 100% of capacity) by "&Inputs!$B$84 -> Shortage (demand above 100% of capacity) by 2031 | B5: =(Inputs!$B$71*Inputs!$B$80*IF(ISNUMBER(Matrix!B6),IF(Matrix!B6<=Inputs!$B$84,1,0),0)+Inputs!$B$71*Inputs!$B$81*IF(ISNUMBER(Matrix!C6),IF(Matrix!C6<=Inputs!$B$84,1,0),0)+Inputs!$B$71*Inputs!$B$82*IF(ISNUMBER(Matrix!D6),IF(Matrix!D6<=Inputs!$B$84,1,0),0)+Inputs!$B$72*Inputs!$B$80*IF(ISNUMBER(Matrix!B7),IF(Matrix!B7<=Inputs!$B$84,1,0),0)+Inputs!$B$72*Inputs!$B$81*IF(ISNUMBER(Matrix!C7),IF(Matrix!C7<=Inputs!$B$84,1,0),0)+Inputs!$B$72*Inputs!$B$82*IF(ISNUMBER(Matrix!D7),IF(Matrix!D7<=Inputs!$B$84,1,0),0)+Inputs!$B$73*Inputs!$B$80*IF(ISNUMBER(Matrix!B8),IF(Matrix!B8<=Inputs!$B$84,1,0),0)+Inputs!$B$73*Inputs!$B$81*IF(ISNUMBER(Matrix!C8),IF(Matrix!C8<=Inputs!$B$84,1,0),0)+Inputs!$B$73*Inputs!$B$82*IF(ISNUMBER(Matrix!D8),IF(Matrix!D8<=Inputs!$B$84,1,0),0)+Inputs!$B$74*Inputs!$B$80*IF(ISNUMBER(Matrix!B9),IF(Matrix!B9<=Inputs!$B$84,1,0),0)+Inputs!$B$74*Inputs!$B$81*IF(ISNUMBER(Matrix!C9),IF(Matrix!C9<=Inputs!$B$84,1,0),0)+Inputs!$B$74*Inputs!$B$82*IF(ISNUMBER(Matrix!D9),IF(Matrix!D9<=Inputs!$B$84,1,0),0)+Inputs!$B$76*Inputs!$B$80*IF(ISNUMBER(Matrix!B11),IF(Matrix!B11<=Inputs!$B$84,1,0),0)+Inputs!$B$76*Inputs!$B$81*IF(ISNUMBER(Matrix!C11),IF(Matrix!C11<=Inputs!$B$84,1,0),0)+Inputs!$B$76*Inputs!$B$82*IF(ISNUMBER(Matrix!D11),IF(Matrix!D11<=Inputs!$B$84,1,0),0)+Inputs!$B$77*Inputs!$B$80*IF(ISNUMBER(Matrix!B12),IF(Matrix!B12<=Inputs!$B$84,1,0),0)+Inputs!$B$77*Inputs!$B$81*IF(ISNUMBER(Matrix!C12),IF(Matrix!C12<=Inputs!$B$84,1,0),0)+Inputs!$B$77*Inputs!$B$82*IF(ISNUMBER(Matrix!D12),IF(Matrix!D12<=Inputs!$B$84,1,0),0)+Inputs!$B$78*Inputs!$B$80*IF(ISNUMBER(Matrix!B13),IF(Matrix!B13<=Inputs!$B$84,1,0),0)+Inputs!$B$78*Inputs!$B$81*IF(ISNUMBER(Matrix!C13),IF(Matrix!C13<=Inputs!$B$84,1,0),0)+Inputs!$B$78*Inputs!$B$82*IF(ISNUMBER(Matrix!D13),IF(Matrix!D13<=Inputs!$B$84,1,0),0)+Inputs!$B$75*Inputs!$B$80*IF(ISNUMBER(Matrix!B10),IF(Matrix!B10<=Inputs!$B$84,1,0),0)+Inputs!$B$75*Inputs!$B$81*IF(ISNUMBER(Matrix!C10),IF(Matrix!C10<=Inputs!$B$84,1,0),0)+Inputs!$B$75*Inputs!$B$82*IF(ISNUMBER(Matrix!D10),IF(Matrix!D10<=Inputs!$B$84,1,0),0))/(SUM(Inputs!$B$71:$B$78)*SUM(Inputs!$B$80:$B$82)) -> 0.425
A6: ="Squeeze or worse (demand above the squeeze line) by "&Inputs!$B$84 -> Squeeze or worse (demand above the squeeze line) by 2031 | B6: =(Inputs!$B$71*Inputs!$B$80*IF(ISNUMBER(Matrix!B17),IF(Matrix!B17<=Inputs!$B$84,1,0),0)+Inputs!$B$71*Inputs!$B$81*IF(ISNUMBER(Matrix!C17),IF(Matrix!C17<=Inputs!$B$84,1,0),0)+Inputs!$B$71*Inputs!$B$82*IF(ISNUMBER(Matrix!D17),IF(Matrix!D17<=Inputs!$B$84,1,0),0)+Inputs!$B$72*Inputs!$B$80*IF(ISNUMBER(Matrix!B18),IF(Matrix!B18<=Inputs!$B$84,1,0),0)+Inputs!$B$72*Inputs!$B$81*IF(ISNUMBER(Matrix!C18),IF(Matrix!C18<=Inputs!$B$84,1,0),0)+Inputs!$B$72*Inputs!$B$82*IF(ISNUMBER(Matrix!D18),IF(Matrix!D18<=Inputs!$B$84,1,0),0)+Inputs!$B$73*Inputs!$B$80*IF(ISNUMBER(Matrix!B19),IF(Matrix!B19<=Inputs!$B$84,1,0),0)+Inputs!$B$73*Inputs!$B$81*IF(ISNUMBER(Matrix!C19),IF(Matrix!C19<=Inputs!$B$84,1,0),0)+Inputs!$B$73*Inputs!$B$82*IF(ISNUMBER(Matrix!D19),IF(Matrix!D19<=Inputs!$B$84,1,0),0)+Inputs!$B$74*Inputs!$B$80*IF(ISNUMBER(Matrix!B20),IF(Matrix!B20<=Inputs!$B$84,1,0),0)+Inputs!$B$74*Inputs!$B$81*IF(ISNUMBER(Matrix!C20),IF(Matrix!C20<=Inputs!$B$84,1,0),0)+Inputs!$B$74*Inputs!$B$82*IF(ISNUMBER(Matrix!D20),IF(Matrix!D20<=Inputs!$B$84,1,0),0)+Inputs!$B$76*Inputs!$B$80*IF(ISNUMBER(Matrix!B22),IF(Matrix!B22<=Inputs!$B$84,1,0),0)+Inputs!$B$76*Inputs!$B$81*IF(ISNUMBER(Matrix!C22),IF(Matrix!C22<=Inputs!$B$84,1,0),0)+Inputs!$B$76*Inputs!$B$82*IF(ISNUMBER(Matrix!D22),IF(Matrix!D22<=Inputs!$B$84,1,0),0)+Inputs!$B$77*Inputs!$B$80*IF(ISNUMBER(Matrix!B23),IF(Matrix!B23<=Inputs!$B$84,1,0),0)+Inputs!$B$77*Inputs!$B$81*IF(ISNUMBER(Matrix!C23),IF(Matrix!C23<=Inputs!$B$84,1,0),0)+Inputs!$B$77*Inputs!$B$82*IF(ISNUMBER(Matrix!D23),IF(Matrix!D23<=Inputs!$B$84,1,0),0)+Inputs!$B$78*Inputs!$B$80*IF(ISNUMBER(Matrix!B24),IF(Matrix!B24<=Inputs!$B$84,1,0),0)+Inputs!$B$78*Inputs!$B$81*IF(ISNUMBER(Matrix!C24),IF(Matrix!C24<=Inputs!$B$84,1,0),0)+Inputs!$B$78*Inputs!$B$82*IF(ISNUMBER(Matrix!D24),IF(Matrix!D24<=Inputs!$B$84,1,0),0)+Inputs!$B$75*Inputs!$B$80*IF(ISNUMBER(Matrix!B21),IF(Matrix!B21<=Inputs!$B$84,1,0),0)+Inputs!$B$75*Inputs!$B$81*IF(ISNUMBER(Matrix!C21),IF(Matrix!C21<=Inputs!$B$84,1,0),0)+Inputs!$B$75*Inputs!$B$82*IF(ISNUMBER(Matrix!D21),IF(Matrix!D21<=Inputs!$B$84,1,0),0))/(SUM(Inputs!$B$71:$B$78)*SUM(Inputs!$B$80:$B$82)) -> 0.47
A8: Today's load, North America, 2026 (demand as a share of capacity) | B8: ='North America'!B38 -> 0.60281636
A10: Second horizon (Inputs section 10) | B10: North America
A11: ="Shortage (demand above 100% of capacity) by "&Inputs!$B$85 -> Shortage (demand above 100% of capacity) by 2028 | B11: =(Inputs!$B$71*Inputs!$B$80*IF(ISNUMBER(Matrix!B6),IF(Matrix!B6<=Inputs!$B$85,1,0),0)+Inputs!$B$71*Inputs!$B$81*IF(ISNUMBER(Matrix!C6),IF(Matrix!C6<=Inputs!$B$85,1,0),0)+Inputs!$B$71*Inputs!$B$82*IF(ISNUMBER(Matrix!D6),IF(Matrix!D6<=Inputs!$B$85,1,0),0)+Inputs!$B$72*Inputs!$B$80*IF(ISNUMBER(Matrix!B7),IF(Matrix!B7<=Inputs!$B$85,1,0),0)+Inputs!$B$72*Inputs!$B$81*IF(ISNUMBER(Matrix!C7),IF(Matrix!C7<=Inputs!$B$85,1,0),0)+Inputs!$B$72*Inputs!$B$82*IF(ISNUMBER(Matrix!D7),IF(Matrix!D7<=Inputs!$B$85,1,0),0)+Inputs!$B$73*Inputs!$B$80*IF(ISNUMBER(Matrix!B8),IF(Matrix!B8<=Inputs!$B$85,1,0),0)+Inputs!$B$73*Inputs!$B$81*IF(ISNUMBER(Matrix!C8),IF(Matrix!C8<=Inputs!$B$85,1,0),0)+Inputs!$B$73*Inputs!$B$82*IF(ISNUMBER(Matrix!D8),IF(Matrix!D8<=Inputs!$B$85,1,0),0)+Inputs!$B$74*Inputs!$B$80*IF(ISNUMBER(Matrix!B9),IF(Matrix!B9<=Inputs!$B$85,1,0),0)+Inputs!$B$74*Inputs!$B$81*IF(ISNUMBER(Matrix!C9),IF(Matrix!C9<=Inputs!$B$85,1,0),0)+Inputs!$B$74*Inputs!$B$82*IF(ISNUMBER(Matrix!D9),IF(Matrix!D9<=Inputs!$B$85,1,0),0)+Inputs!$B$76*Inputs!$B$80*IF(ISNUMBER(Matrix!B11),IF(Matrix!B11<=Inputs!$B$85,1,0),0)+Inputs!$B$76*Inputs!$B$81*IF(ISNUMBER(Matrix!C11),IF(Matrix!C11<=Inputs!$B$85,1,0),0)+Inputs!$B$76*Inputs!$B$82*IF(ISNUMBER(Matrix!D11),IF(Matrix!D11<=Inputs!$B$85,1,0),0)+Inputs!$B$77*Inputs!$B$80*IF(ISNUMBER(Matrix!B12),IF(Matrix!B12<=Inputs!$B$85,1,0),0)+Inputs!$B$77*Inputs!$B$81*IF(ISNUMBER(Matrix!C12),IF(Matrix!C12<=Inputs!$B$85,1,0),0)+Inputs!$B$77*Inputs!$B$82*IF(ISNUMBER(Matrix!D12),IF(Matrix!D12<=Inputs!$B$85,1,0),0)+Inputs!$B$78*Inputs!$B$80*IF(ISNUMBER(Matrix!B13),IF(Matrix!B13<=Inputs!$B$85,1,0),0)+Inputs!$B$78*Inputs!$B$81*IF(ISNUMBER(Matrix!C13),IF(Matrix!C13<=Inputs!$B$85,1,0),0)+Inputs!$B$78*Inputs!$B$82*IF(ISNUMBER(Matrix!D13),IF(Matrix!D13<=Inputs!$B$85,1,0),0)+Inputs!$B$75*Inputs!$B$80*IF(ISNUMBER(Matrix!B10),IF(Matrix!B10<=Inputs!$B$85,1,0),0)+Inputs!$B$75*Inputs!$B$81*IF(ISNUMBER(Matrix!C10),IF(Matrix!C10<=Inputs!$B$85,1,0),0)+Inputs!$B$75*Inputs!$B$82*IF(ISNUMBER(Matrix!D10),IF(Matrix!D10<=Inputs!$B$85,1,0),0))/(SUM(Inputs!$B$71:$B$78)*SUM(Inputs!$B$80:$B$82)) -> 0.4
A12: ="Squeeze or worse (demand above the squeeze line) by "&Inputs!$B$85 -> Squeeze or worse (demand above the squeeze line) by 2028 | B12: =(Inputs!$B$71*Inputs!$B$80*IF(ISNUMBER(Matrix!B17),IF(Matrix!B17<=Inputs!$B$85,1,0),0)+Inputs!$B$71*Inputs!$B$81*IF(ISNUMBER(Matrix!C17),IF(Matrix!C17<=Inputs!$B$85,1,0),0)+Inputs!$B$71*Inputs!$B$82*IF(ISNUMBER(Matrix!D17),IF(Matrix!D17<=Inputs!$B$85,1,0),0)+Inputs!$B$72*Inputs!$B$80*IF(ISNUMBER(Matrix!B18),IF(Matrix!B18<=Inputs!$B$85,1,0),0)+Inputs!$B$72*Inputs!$B$81*IF(ISNUMBER(Matrix!C18),IF(Matrix!C18<=Inputs!$B$85,1,0),0)+Inputs!$B$72*Inputs!$B$82*IF(ISNUMBER(Matrix!D18),IF(Matrix!D18<=Inputs!$B$85,1,0),0)+Inputs!$B$73*Inputs!$B$80*IF(ISNUMBER(Matrix!B19),IF(Matrix!B19<=Inputs!$B$85,1,0),0)+Inputs!$B$73*Inputs!$B$81*IF(ISNUMBER(Matrix!C19),IF(Matrix!C19<=Inputs!$B$85,1,0),0)+Inputs!$B$73*Inputs!$B$82*IF(ISNUMBER(Matrix!D19),IF(Matrix!D19<=Inputs!$B$85,1,0),0)+Inputs!$B$74*Inputs!$B$80*IF(ISNUMBER(Matrix!B20),IF(Matrix!B20<=Inputs!$B$85,1,0),0)+Inputs!$B$74*Inputs!$B$81*IF(ISNUMBER(Matrix!C20),IF(Matrix!C20<=Inputs!$B$85,1,0),0)+Inputs!$B$74*Inputs!$B$82*IF(ISNUMBER(Matrix!D20),IF(Matrix!D20<=Inputs!$B$85,1,0),0)+Inputs!$B$76*Inputs!$B$80*IF(ISNUMBER(Matrix!B22),IF(Matrix!B22<=Inputs!$B$85,1,0),0)+Inputs!$B$76*Inputs!$B$81*IF(ISNUMBER(Matrix!C22),IF(Matrix!C22<=Inputs!$B$85,1,0),0)+Inputs!$B$76*Inputs!$B$82*IF(ISNUMBER(Matrix!D22),IF(Matrix!D22<=Inputs!$B$85,1,0),0)+Inputs!$B$77*Inputs!$B$80*IF(ISNUMBER(Matrix!B23),IF(Matrix!B23<=Inputs!$B$85,1,0),0)+Inputs!$B$77*Inputs!$B$81*IF(ISNUMBER(Matrix!C23),IF(Matrix!C23<=Inputs!$B$85,1,0),0)+Inputs!$B$77*Inputs!$B$82*IF(ISNUMBER(Matrix!D23),IF(Matrix!D23<=Inputs!$B$85,1,0),0)+Inputs!$B$78*Inputs!$B$80*IF(ISNUMBER(Matrix!B24),IF(Matrix!B24<=Inputs!$B$85,1,0),0)+Inputs!$B$78*Inputs!$B$81*IF(ISNUMBER(Matrix!C24),IF(Matrix!C24<=Inputs!$B$85,1,0),0)+Inputs!$B$78*Inputs!$B$82*IF(ISNUMBER(Matrix!D24),IF(Matrix!D24<=Inputs!$B$85,1,0),0)+Inputs!$B$75*Inputs!$B$80*IF(ISNUMBER(Matrix!B21),IF(Matrix!B21<=Inputs!$B$85,1,0),0)+Inputs!$B$75*Inputs!$B$81*IF(ISNUMBER(Matrix!C21),IF(Matrix!C21<=Inputs!$B$85,1,0),0)+Inputs!$B$75*Inputs!$B$82*IF(ISNUMBER(Matrix!D21),IF(Matrix!D21<=Inputs!$B$85,1,0),0))/(SUM(Inputs!$B$71:$B$78)*SUM(Inputs!$B$80:$B$82)) -> 0.47

Sheet Worker check
A1: Worker check: how much demand can people at work explain?
A2: A cross check only; nothing here feeds the model. It asks whether the demand paths are plausible from North American workers alone. Inputs are on the Inputs sheet, section 11.
A4: Usage tier | B4: Tokens per person per day | C4: Share of workers 2026 | D4: Share of workers 2029
A5: =Inputs!A89 -> Non users | B5: =Inputs!B89 -> 0 | C5: =Inputs!C89 -> 0.48 | D5: =Inputs!D89 -> 0.3
A6: =Inputs!A90 -> Light users (a few times a year to monthly) | B6: =Inputs!B90 -> 20000 | C6: =Inputs!C90 -> 0.22 | D6: =Inputs!D90 -> 0.2
A7: =Inputs!A91 -> Weekly users | B7: =Inputs!B91 -> 100000 | C7: =Inputs!C91 -> 0.15 | D7: =Inputs!D91 -> 0.2
A8: =Inputs!A92 -> Daily users | B8: =Inputs!B92 -> 500000 | C8: =Inputs!C92 -> 0.14 | D8: =Inputs!D92 -> 0.25
A9: =Inputs!A93 -> Power users (daily agentic work) | B9: =Inputs!B93 -> 15000000 | C9: =Inputs!C93 -> 0.01 | D9: =Inputs!D93 -> 0.05
A10: Check: shares sum to | C10: =SUM(C5:C9) -> 1 | D10: =SUM(D5:D9) -> 1
A12: Employed people, United States plus Canada (millions) | B12: =Inputs!B94 -> 183.9
A13: Worker token demand 2026 (trillion tokens per day) | B13: =B12*SUMPRODUCT(B5:B9,C5:C9)/1000000 -> 44.02566
A14: Worker token demand 2029 (trillion tokens per day) | B14: =B12*SUMPRODUCT(B5:B9,D5:D9)/1000000 -> 165.3261
A15: Multiple from the change in mix alone, 2026 to 2029 | B15: =B14/B13 -> 3.7552214
A16: Same, as a yearly growth multiple | B16: =B15^(1/3) -> 1.554337
A17: Worker demand as a share of all North American origin demand, 2026 | B17: =B13/(Inputs!$B$15*Inputs!$B$95) -> 0.35220528
